Workbook

Sheet Summary
A1: No | B1: Katalog | C1: Product | D1: Stock | E1: Jenis | F1: Harga | G1: Garansi | H1: Deskripsi | J1: RINGKASAN | K1: JUMLAH
A2: 1 | B2: Gemini | C2: Gemini Google AI Plus 400GB 12 bulan | D2: =P01_Gemini_Plus12!B4 -> 0 | E2: Product | F2: 15000 | G2: Full garansi 12 bulan | H2: FITUR: Gemini di aplikasi Google, Deep Research, akses lebih tinggi ke fitur AI dibanding akun gratis, pembuatan gambar/video sesuai kuota paket, Gemini Notebook/NotebookLM, serta Gemini di Gmail (sesuai ketersediaan). BENEFIT: Cloud storage 400 GB untuk Gmail, Drive, dan Google Photos selama paket aktif; mendukung penulisan, riset, belajar, penyusunan materi, dan produktivitas. AKTIVASI: Terima metode aktivasi yang disediakan pada pesanan; login ke Akun Google yang memenuhi syarat; buka tautan redeem resmi jika diberikan, cek detail promo, konfirmasi; verifikasi paket di Google One dan Gemini. GARANSI: Garansi penuh 12 bulan menurut ketentuan penjual; klaim melalui ID order dan bukti gangguan; tidak berarti semua pembatasan layanan Google ditanggung. CATATAN: Durasi 12 bulan adalah spesifikasi penawaran toko; jangan menyimpulkan semua akun/negara memenuhi syarat. Fitur dan kuota bergantung region, perangkat, perubahan Google, dan status akun. | J2: Total SKU | K2: =COUNTA(C2:C22) -> 21
A3: 2 | B3: Gemini | C3: Gemini Google AI Pro 5TB 18 bulan | D3: =P02_Gemini_Pro18!B4 -> 0 | E3: FRESH BY MADE | F3: 25000 | G3: 2 jam | H3: FITUR: Fitur Google AI Plus ditambah akses Gemini yang lebih besar, Deep Research, Gemini di Gmail/Docs/Sheets, peningkatan akses AI Studio dan Google Flow, serta tools pembuatan gambar/video sesuai paket. BENEFIT: Penyimpanan Google One 5 TB untuk Gmail/Drive/Photos; cocok untuk pekerjaan dokumen besar, riset, coding berbantuan AI, dan produksi konten yang membutuhkan kuota lebih tinggi. AKTIVASI: Ikuti link redeem/undangan resmi dari pesanan bila ada; login ke Akun Google pribadi yang eligible; tinjau rincian penawaran 18 bulan sebelum konfirmasi; cek Google One > paket dan masa berlaku. GARANSI: Garansi seller 2 jam sejak aktivasi/penyerahan sesuai kebijakan toko; simpan bukti saat paket tidak sesuai. CATATAN: Durasi 18 bulan adalah penawaran seller dan bukan durasi standar yang dijamin Google untuk semua pelanggan. Cek penagihan, negara, serta metode aktivasi sebelum checkout; beberapa benefit dibatasi wilayah. | J3: Jenis Product | K3: =COUNTIF(E2:E22,"Product") -> 14
A4: 3 | B4: Gemini | C4: Gemini Google AI Ultra 20TB 24 bulan | D4: =P03_Gemini_Ultra24!B4 -> 0 | E4: FRESH BY MADE | F4: 155000 | G4: 6 bulan | H4: FITUR: Akses tingkat Ultra ke Gemini dan Deep Research dengan batas lebih tinggi; dukungan fitur AI kreatif di Google Flow, pembuatan video/gambar, Gemini Notebook, AI Studio dan alat Google lainnya yang tercantum pada paket Ultra. BENEFIT: Storage Google One 20 TB pada varian yang ditawarkan; cocok untuk kreator, riset berat, dan penggunaan fitur AI lanjutan dengan limit lebih besar daripada Pro (tetap tidak unlimited). AKTIVASI: Aktivasi melalui alur Google One resmi sesuai instruksi pesanan; login ke Akun Google eligible; tinjau syarat promo/periode 24 bulan; pastikan di Google One terlihat paket Ultra dan storage 20 TB. GARANSI: Garansi seller 6 bulan, tunduk syarat klaim ID order dan status paket saat pengajuan. CATATAN: Periode 24 bulan adalah spesifikasi penawaran toko, bukan janji standar Google. Ketersediaan fitur AI tertentu, termasuk layanan tambahan, berbeda menurut region, usia, dan kuota. | J4: Jenis Jasa | K4: =COUNTIF(E2:E22,"Jasa") -> 4
A5: 4 | B5: Claude | C5: Claude Pro 1 Bulan (Gift Pack) | D5: =P04_Claude_Gift1!B4 -> 0 | E5: Product | F5: 175000 | G5: 25 hari | H5: FITUR: Claude Pro: batas pemakaian lebih tinggi daripada Free, akses prioritas saat trafik tinggi, kemampuan analisis/penulisan, pengerjaan tugas multi-langkah, akses Claude Code dan fitur Pro yang tersedia. BENEFIT: Aktivasi paket Pro melalui gift subscription untuk penggunaan 1 bulan sesuai nominal hadiah yang valid; bekerja untuk chat, dokumen, coding, perencanaan, dan ide konten. Pemakaian Claude API Console tidak termasuk. AKTIVASI: Terima email/link/kode gift yang valid; buka claude.ai/gift/redeem atau tautan hadiah; masuk/buat akun Claude; periksa paket dan masa aktif pada layar redeem; konfirmasi. Gift tidak bisa di-stack sekaligus; pelanggan subscription mobile perlu memperhatikan ketentuan redeem. GARANSI: Garansi penjual 25 hari; simpan link/kode dan bukti aktivasi. Klaim sesuai syarat toko selama masa garansi, bukan penggantian resmi Anthropic. CATATAN: Durasi gift 1 bulan harus cocok dengan rincian gift aktual. Jika hadiah sudah kedaluwarsa, pernah dipakai, atau akun tidak eligible, jangan menjanjikan aktivasi pasti. Gift resmi memiliki masa klaim dan aturan non-stacking. | J5: Fresh by Made | K5: =COUNTIF(E2:E22,"FRESH BY MADE") -> 3
A6: 5 | B6: Claude | C6: Claude Pro 3 Bulan (Gift Pack) | D6: =P05_Claude_Gift3!B4 -> 0 | E6: Product | F6: 370000 | G6: 85 hari | H6: FITUR: Claude Pro: batas pemakaian lebih tinggi daripada Free, akses prioritas saat trafik tinggi, kemampuan analisis/penulisan, pengerjaan tugas multi-langkah, akses Claude Code dan fitur Pro yang tersedia. BENEFIT: Aktivasi paket Pro melalui gift subscription untuk penggunaan 3 bulan sesuai nominal hadiah yang valid; bekerja untuk chat, dokumen, coding, perencanaan, dan ide konten. Pemakaian Claude API Console tidak termasuk. AKTIVASI: Terima email/link/kode gift yang valid; buka claude.ai/gift/redeem atau tautan hadiah; masuk/buat akun Claude; periksa paket dan masa aktif pada layar redeem; konfirmasi. Gift tidak bisa di-stack sekaligus; pelanggan subscription mobile perlu memperhatikan ketentuan redeem. GARANSI: Garansi penjual 85 hari; simpan link/kode dan bukti aktivasi. Klaim sesuai syarat toko selama masa garansi, bukan penggantian resmi Anthropic. CATATAN: Durasi gift 3 bulan harus cocok dengan rincian gift aktual. Jika hadiah sudah kedaluwarsa, pernah dipakai, atau akun tidak eligible, jangan menjanjikan aktivasi pasti. Gift resmi memiliki masa klaim dan aturan non-stacking. | J6: Harga belum diisi | K6: =COUNTBLANK(F2:F22) -> 0
A7: 6 | B7: Claude | C7: Claude Pro 6 Bulan (Gift Pack) | D7: =P06_Claude_Gift6!B4 -> 0 | E7: Product | F7: 650000 | G7: 178 hari | H7: FITUR: Claude Pro: batas pemakaian lebih tinggi daripada Free, akses prioritas saat trafik tinggi, kemampuan analisis/penulisan, pengerjaan tugas multi-langkah, akses Claude Code dan fitur Pro yang tersedia. BENEFIT: Aktivasi paket Pro melalui gift subscription untuk penggunaan 6 bulan sesuai nominal hadiah yang valid; bekerja untuk chat, dokumen, coding, perencanaan, dan ide konten. Pemakaian Claude API Console tidak termasuk. AKTIVASI: Terima email/link/kode gift yang valid; buka claude.ai/gift/redeem atau tautan hadiah; masuk/buat akun Claude; periksa paket dan masa aktif pada layar redeem; konfirmasi. Gift tidak bisa di-stack sekaligus; pelanggan subscription mobile perlu memperhatikan ketentuan redeem. GARANSI: Garansi penjual 178 hari; simpan link/kode dan bukti aktivasi. Klaim sesuai syarat toko selama masa garansi, bukan penggantian resmi Anthropic. CATATAN: Durasi gift 6 bulan harus cocok dengan rincian gift aktual. Jika hadiah sudah kedaluwarsa, pernah dipakai, atau akun tidak eligible, jangan menjanjikan aktivasi pasti. Gift resmi memiliki masa klaim dan aturan non-stacking.
A8: 7 | B8: Claude | C8: Claude Pro 12 Bulan (Gift Pack) | D8: =P07_Claude_Gift12!B4 -> 0 | E8: Product | F8: 850000 | G8: 340 hari | H8: FITUR: Claude Pro: batas pemakaian lebih tinggi daripada Free, akses prioritas saat trafik tinggi, kemampuan analisis/penulisan, pengerjaan tugas multi-langkah, akses Claude Code dan fitur Pro yang tersedia. BENEFIT: Aktivasi paket Pro melalui gift subscription untuk penggunaan 12 bulan sesuai nominal hadiah yang valid; bekerja untuk chat, dokumen, coding, perencanaan, dan ide konten. Pemakaian Claude API Console tidak termasuk. AKTIVASI: Terima email/link/kode gift yang valid; buka claude.ai/gift/redeem atau tautan hadiah; masuk/buat akun Claude; periksa paket dan masa aktif pada layar redeem; konfirmasi. Gift tidak bisa di-stack sekaligus; pelanggan subscription mobile perlu memperhatikan ketentuan redeem. GARANSI: Garansi penjual 340 hari; simpan link/kode dan bukti aktivasi. Klaim sesuai syarat toko selama masa garansi, bukan penggantian resmi Anthropic. CATATAN: Durasi gift 12 bulan harus cocok dengan rincian gift aktual. Jika hadiah sudah kedaluwarsa, pernah dipakai, atau akun tidak eligible, jangan menjanjikan aktivasi pasti. Gift resmi memiliki masa klaim dan aturan non-stacking. | J8: ATURAN STOCK | K8: KETERANGAN
A9: 8 | B9: Claude | C9: Claude Startup ($1000) 6 bulan — Head Account | D9: =P08_Claude_Head!B4 -> 0 | E9: Product | F9: 7900000 | G9: 1 bulan | H9: FITUR: Program Claude Startups untuk organisasi yang disetujui: kredit Claude API sekali klaim sebesar US$1.000 dengan masa berlaku 6 bulan; pada penawaran program yang relevan, dapat menyertakan hingga 5 Premium seats Claude Team selama 1 tahun, rate limit API lebih tinggi, dan benefit partner. BENEFIT: Kredit dipakai untuk pemakaian first-party API di Claude Console (bukan saldo tunai, bukan kredit AWS Bedrock/Vertex). Fitur Team dan partner hanya ada jika organisasi benar-benar memperoleh alokasi dan menebusnya. AKTIVASI: Penanggung jawab organisasi yang memenuhi syarat melakukan aplikasi resmi, menerima approval, login ke Claude Console dan mengklaim benefit pada halaman Startups. Jika ditawarkan akses head, pastikan kepemilikan/legalitas dan otorisasi organisasi sebelum transfer administrasi. GARANSI: Garansi penjual 1 bulan sesuai perjanjian; nilai kredit dan jangka waktu harus diverifikasi di Console pada saat transaksi. CATATAN: SANGAT PENTING: kredit promosi tidak boleh diasumsikan dapat diperjualbelikan/dialihkan. Program telah berubah dan cohort 2026 sempat ditutup. Jangan menjanjikan account transfer, transferable credit, atau seats tanpa persetujuan Anthropic; nilai kredit tidak sama dengan akses unlimited. | J9: Product | K9: Jumlah data valid berstatus AVAILABLE
A10: 9 | B10: Claude | C10: Claude Invite Reguler 1 bulan | D10: DARI BOT | E10: Jasa | F10: 120000 | G10: Belum ditentukan | H10: FITUR: Akses anggota Claude Team pada kursi yang ditetapkan organisasi, untuk pekerjaan chat, riset, penulisan dan coding sesuai tipe seat (Standard/Premium). Batas pemakaian mengikuti tier, bukan unlimited. BENEFIT: Bisa menggunakan akun Claude pribadi yang diundang oleh organisasi yang sah; pengelolaan anggota, izin, dan seat dilakukan oleh admin organisasi. AKTIVASI: Pembeli memberikan alamat email yang diizinkan organisasi; admin mengundang lewat pengaturan anggota; pembeli menerima email undangan, masuk ke Claude, lalu bergabung; periksa tier dan tanggal masa aktif. GARANSI: Belum ada periode garansi yang ditentukan seller; minta konfirmasi tertulis sebelum pembelian. CATATAN: Invite bukan head/owner account. Seat dapat dicabut organisasi. Email harus sesuai domain yang diizinkan. Pastikan kerja sama dan penugasan pengguna mematuhi ketentuan Anthropic. | J10: Jasa | K10: Tetap memakai stok/alur bot lama
A11: 10 | B11: Claude | C11: Claude Invite Startup per seat per bulan | D11: DARI BOT | E11: Jasa | F11: 600000 | G11: Belum ditentukan | H11: FITUR: Akses melalui seat organisasi Claude Team yang memperoleh program Startups. Bila yang diundang adalah Premium seat, kuota Team Premium dapat lebih tinggi daripada Standard dan menyediakan akses Claude Code sesuai hak paket. BENEFIT: Keanggotaan seat untuk 1 bulan sesuai alokasi riil dan status organisasi; pengguna tidak otomatis menerima kredit API US$1.000 milik organisasi. AKTIVASI: Berikan email kerja sesuai domain yang diizinkan; admin yang berwenang menugaskan seat, mengirim invite melalui Team Settings, pengguna menerima undangan dan memeriksa tier serta masa berlaku. Jangan memakai login head bersama. GARANSI: Garansi belum ditentukan oleh seller; konfirmasi masa dan cakupan klaim sebelum listing live. CATATAN: Penawaran seat per bulan; benefit startup tidak boleh diasumsikan dapat dijual ulang. Periksa jumlah seat, status grant, tanggal berakhir akses Team, dan persetujuan Anthropic atas penggunaan komersial. | J11: FRESH BY MADE | K11: 1 pesan template; tidak mengurangi stok
A12: 11 | B12: Claude | C12: Claude Invite Startup per seat 6 bulan | D12: DARI BOT | E12: Jasa | F12: 2780000 | G12: Belum ditentukan | H12: FITUR: Akses melalui seat organisasi Claude Team yang memperoleh program Startups. Bila yang diundang adalah Premium seat, kuota Team Premium dapat lebih tinggi daripada Standard dan menyediakan akses Claude Code sesuai hak paket. BENEFIT: Keanggotaan seat untuk 6 bulan sesuai alokasi riil dan status organisasi; pengguna tidak otomatis menerima kredit API US$1.000 milik organisasi. AKTIVASI: Berikan email kerja sesuai domain yang diizinkan; admin yang berwenang menugaskan seat, mengirim invite melalui Team Settings, pengguna menerima undangan dan memeriksa tier serta masa berlaku. Jangan memakai login head bersama. GARANSI: Garansi belum ditentukan oleh seller; konfirmasi masa dan cakupan klaim sebelum listing live. CATATAN: Penawaran seat per 6 bulan; benefit startup tidak boleh diasumsikan dapat dijual ulang. Periksa jumlah seat, status grant, tanggal berakhir akses Team, dan persetujuan Anthropic atas penggunaan komersial. | J12: Kosong | K12: Belum dimasukkan, bukan stok palsu
A13: 12 | B13: ChatGPT | C13: ChatGPT Plus UPI 30 hari | D13: =P09_GPT_UPI30!B4 -> 0 | E13: Product | F13: 95000 | G13: 7 hari | H13: FITUR: Fitur ChatGPT Plus yang tersedia pada akun eligible: pilihan model lebih luas, penalaran lanjutan, unggah/analisis file, pembuatan gambar, percakapan suara dan tools riset sesuai batas paket. BENEFIT: Penggunaan ChatGPT lebih nyaman untuk coding, belajar, penulisan, analisis data, brainstorming, dan pekerjaan multi-langkah dibanding fitur Free; tidak termasuk kredit API. AKTIVASI: Nama 'UPI' adalah kode varian toko, bukan tier resmi ChatGPT. Metode aktivasi bergantung stok: ikuti instruksi order/admin yang sah; login ke akun yang ditetapkan; verifikasi status Plus di Settings > Plan dan masa 30 hari. GARANSI: Garansi penjual 7 hari; klaim dengan Order ID, tanggal aktivasi, dan bukti masalah. CATATAN: Belum ada harga yang diberikan seller. Jangan menyebut metode UPI sebagai keistimewaan resmi Plus. Hindari membagikan OTP/password ke pihak tak tepercaya; cek ketentuan akun dan penagihan.
A14: 13 | B14: ChatGPT | C14: ChatGPT Plus Reguler 1 bulan | D14: =P10_GPT_Reguler1!B4 -> 0 | E14: Product | F14: 125000 | G14: 20 hari | H14: FITUR: ChatGPT Plus reguler: penggunaan model lebih luas, opsi reasoning, file upload/analisis, voice, image generation, dan Deep Research sesuai akses akun. BENEFIT: Mendukung penulisan, programming, brainstorming, riset, presentasi, dan olah dokumen dengan limit lebih besar daripada Free. Tidak menyertakan pemakaian OpenAI API. AKTIVASI: Aktivasi berlangganan melalui akun ChatGPT yang memenuhi syarat dan mekanisme pembayaran/aktivasi yang dijelaskan saat order; setelah selesai, masuk ke aplikasi ChatGPT dan cek Settings > Plan. GARANSI: Garansi toko 20 hari setelah aktivasi menurut syarat seller; tidak berarti fitur ChatGPT selalu tanpa batas. CATATAN: Harga belum diberikan. Pastikan metode aktivasi yang dijual sah, durasi 1 bulan jelas, dan pelanggan tidak diminta menyerahkan kredensial sensitif.
A15: 14 | B15: ChatGPT | C15: ChatGPT Plus Trial 30 hari | D15: =P11_GPT_Trial30!B4 -> 0 | E15: Product | F15: 89000 | G15: Full garansi 30 hari | H15: FITUR: Selama promo aktif dan benar-benar memberi akses Plus: opsi penalaran lebih luas, penggunaan file, suara, pembuatan gambar, serta fitur AI berbayar lainnya sesuai eligibility dan kuota saat itu. BENEFIT: Varian trial dengan target masa akses 30 hari; cocok untuk mencoba workflow ChatGPT Plus tanpa mengasumsikan ketersediaan permanen. AKTIVASI: Jika diberikan link promo resmi: buka link, login/buat akun ChatGPT, baca masa trial dan syarat akun, lalu terima penawaran hanya jika detail di halaman sesuai; cek Settings > Plan. Jika metode berbeda, harus dijelaskan seller sebelum pembayaran. GARANSI: Garansi penuh 30 hari menurut ketentuan penjual untuk paket trial yang berhasil diaktifkan. CATATAN: Durasi 30 hari adalah spesifikasi listing, BUKAN jaminan setiap akun eligible. Promo bisa dibatasi wilayah/akun, tidak bisa ditumpuk, dan sebagian promo auto-renew berbayar jika tidak dibatalkan sebelum berakhir; cek layar checkout.
A16: 15 | B16: ChatGPT | C16: ChatGPT Plus Trial 25 hari | D16: =P12_GPT_Trial25!B4 -> 0 | E16: Product | F16: 78000 | G16: Full garansi 25 hari | H16: FITUR: Selama promo aktif dan benar-benar memberi akses Plus: opsi penalaran lebih luas, penggunaan file, suara, pembuatan gambar, serta fitur AI berbayar lainnya sesuai eligibility dan kuota saat itu. BENEFIT: Varian trial dengan target masa akses 25 hari; cocok untuk mencoba workflow ChatGPT Plus tanpa mengasumsikan ketersediaan permanen. AKTIVASI: Jika diberikan link promo resmi: buka link, login/buat akun ChatGPT, baca masa trial dan syarat akun, lalu terima penawaran hanya jika detail di halaman sesuai; cek Settings > Plan. Jika metode berbeda, harus dijelaskan seller sebelum pembayaran. GARANSI: Garansi penuh 25 hari menurut ketentuan penjual untuk paket trial yang berhasil diaktifkan. CATATAN: Durasi 25 hari adalah spesifikasi listing, BUKAN jaminan setiap akun eligible. Promo bisa dibatasi wilayah/akun, tidak bisa ditumpuk, dan sebagian promo auto-renew berbayar jika tidak dibatalkan sebelum berakhir; cek layar checkout.
A17: 16 | B17: ChatGPT | C17: ChatGPT Plus Trial 15 hari | D17: =P13_GPT_Trial15!B4 -> 0 | E17: Product | F17: 55000 | G17: Full garansi 15 hari | H17: FITUR: Selama promo aktif dan benar-benar memberi akses Plus: opsi penalaran lebih luas, penggunaan file, suara, pembuatan gambar, serta fitur AI berbayar lainnya sesuai eligibility dan kuota saat itu. BENEFIT: Varian trial dengan target masa akses 15 hari; cocok untuk mencoba workflow ChatGPT Plus tanpa mengasumsikan ketersediaan permanen. AKTIVASI: Jika diberikan link promo resmi: buka link, login/buat akun ChatGPT, baca masa trial dan syarat akun, lalu terima penawaran hanya jika detail di halaman sesuai; cek Settings > Plan. Jika metode berbeda, harus dijelaskan seller sebelum pembayaran. GARANSI: Garansi penuh 15 hari menurut ketentuan penjual untuk paket trial yang berhasil diaktifkan. CATATAN: Durasi 15 hari adalah spesifikasi listing, BUKAN jaminan setiap akun eligible. Promo bisa dibatasi wilayah/akun, tidak bisa ditumpuk, dan sebagian promo auto-renew berbayar jika tidak dibatalkan sebelum berakhir; cek layar checkout.
A18: 17 | B18: ChatGPT | C18: ChatGPT Plus Trial 7 hari | D18: =P14_GPT_Trial7!B4 -> 0 | E18: Product | F18: 45000 | G18: Full garansi 7 hari | H18: FITUR: Selama promo aktif dan benar-benar memberi akses Plus: opsi penalaran lebih luas, penggunaan file, suara, pembuatan gambar, serta fitur AI berbayar lainnya sesuai eligibility dan kuota saat itu. BENEFIT: Varian trial dengan target masa akses 7 hari; cocok untuk mencoba workflow ChatGPT Plus tanpa mengasumsikan ketersediaan permanen. AKTIVASI: Jika diberikan link promo resmi: buka link, login/buat akun ChatGPT, baca masa trial dan syarat akun, lalu terima penawaran hanya jika detail di halaman sesuai; cek Settings > Plan. Jika metode berbeda, harus dijelaskan seller sebelum pembayaran. GARANSI: Garansi penuh 7 hari menurut ketentuan penjual untuk paket trial yang berhasil diaktifkan. CATATAN: Durasi 7 hari adalah spesifikasi listing, BUKAN jaminan setiap akun eligible. Promo bisa dibatasi wilayah/akun, tidak bisa ditumpuk, dan sebagian promo auto-renew berbayar jika tidak dibatalkan sebelum berakhir; cek layar checkout.
A19: 18 | B19: Muse | C19: Muse Token 3B (Referral) | D19: DARI BOT | E19: Jasa | F19: 25000 | G19: Tidak ada | H19: FITUR: Layanan bantuan proses referral Muse Token 3B sesuai program yang sedang aktif; nilai token dan syarat klaim mengikuti mekanisme penyelenggara. BENEFIT: Mempermudah pembeli mengikuti alur referral dan memeriksa status klaim bila memenuhi syarat. Bukan penjualan saldo token yang otomatis terisi sebelum verifikasi. AKTIVASI: Pembeli mengikuti langkah resmi program Muse sesuai instruksi yang disediakan setelah order; masukkan kode referral secara tepat pada kolom yang benar, konfirmasi, dan periksa status/kuota di layanan Muse. Jangan mengirim password atau OTP. GARANSI: Tidak ada garansi. Kesalahan input kode referral oleh pelanggan tidak ditanggung penjual, sebagaimana ketentuan produk. CATATAN: Belum ada sumber resmi program referral/3B token yang dapat diverifikasi dari data seller. Cek apakah klaim benar-benar tersedia sebelum publikasi; manfaat tidak boleh dijanjikan sebagai saldo pasti.
A20: 19 | B20: Canva | C20: Canva Education Lifetime — Invite | D20: =F01_Canva_Fresh!B4 -> 0 | E20: FRESH BY MADE | F20: 15000 | G20: Belum ditentukan | H20: FITUR: Canva for Education memberi akses template pembelajaran, elemen desain, presentasi, animasi, kolaborasi kelas, materi ajar, dan alat desain sesuai peran/kebijakan tim sekolah. BENEFIT: Mendukung guru dan siswa yang memenuhi syarat untuk membuat materi kelas, poster, infografis, presentasi dan proyek sekolah dengan banyak fitur premium. AKTIVASI: FRESH BY MADE: setelah order masuk, admin memproses pembuatan/undangan sesuai aturan kelayakan. Pengguna yang memenuhi syarat menerima undangan tim sekolah resmi, masuk ke akun Canva, lalu memeriksa akses Education. Pesan otomatis disusun seller sendiri. GARANSI: Garansi belum ditentukan; jangan menyatakan garansi lifetime sampai ada kebijakan tertulis. CATATAN: Canva for Education GRATIS untuk pendidik/siswa K-12 yang memenuhi syarat; label 'lifetime' tidak dijamin oleh Canva dan akses bisa dicabut saat tidak eligible. Undangan atau penjualan eksternal harus sesuai ketentuan. Stok FRESH BY MADE adalah ketersediaan layanan (1 pesan), bukan akun jadi.
A21: 20 | B21: Netflix | C21: Netflix 1P1U | D21: =P15_Netflix_1P1U!B4 -> 0 | E21: Product | F21: 45000 | G21: Full garansi (durasi belum ditentukan) | H21: FITUR: Netflix menyediakan katalog film/serial, profil dengan rekomendasi dan daftar tontonan pribadi, pengaturan bahasa/subtitel, dan tontonan lintas perangkat sesuai hak paket. BENEFIT: Varian 1P1U dipasarkan sebagai satu profil untuk satu pengguna, mempermudah memisahkan riwayat tontonan dalam household yang sama bila paket mengizinkan. AKTIVASI: Setelah pembelian, ikuti metode akses sah yang disediakan seller; login di aplikasi/situs Netflix, pilih profil yang ditentukan, atur preferensi bila diizinkan, dan mulai menonton. GARANSI: Seller menyebut full garansi, tetapi durasinya BELUM ditentukan. Minta ketentuan klaim sebelum listing aktif. CATATAN: Profil Netflix tidak sama dengan langganan mandiri. Netflix membatasi berbagi akun di luar household; gunakan opsi Extra Member resmi jika lintas household dan tersedia. Jangan menjanjikan akses lintas rumah tangga yang melanggar ketentuan.
A22: 21 | B22: YouTube | C22: YouTube Premium (Akun Seller) 3 bulan | D22: =P16_YouTube_3mo!B4 -> 0 | E22: Product | F22: 45000 | G22: 2 bulan | H22: FITUR: YouTube Premium mencakup pemutaran tanpa iklan YouTube yang memenuhi syarat, video offline, pemutaran latar belakang, dan YouTube Music Premium sesuai negara/perangkat. BENEFIT: Lebih nyaman menonton video dan mendengarkan musik saat berpindah aplikasi atau dalam perjalanan; unduhan bisa ditonton offline dalam ketentuan aplikasi. AKTIVASI: Metode 'Akun Seller': setelah order, pembeli menerima instruksi akun yang disediakan secara sah, masuk ke YouTube/Google, dan memverifikasi indikator Premium di menu Keanggotaan berbayar; jangan mengganti pengaturan keamanan tanpa izin pemilik. GARANSI: Garansi toko 2 bulan untuk paket 3 bulan. Sesuai syarat yang seller berikan, garansi tidak berlaku jika akun tidak aktif; definisi tidak aktif perlu ditetapkan tertulis. CATATAN: Akun seller berbeda dari aktivasi pada akun Google pribadi pembeli. Konfirmasikan kebijakan login/perangkat dan hak pemakaian; manfaat YouTube Premium bisa terbatas negara/konten.

Sheet Panduan & Mapping
A1: IDSE | PANDUAN INPUT & PEMETAAN STOCK
A3: SHEET | B3: TUJUAN
A4: Summary | B4: Tabel master; 8 header pertama pada baris 1 harus dipertahankan untuk importer bot/web.
A5: P01...P16 | B5: Tiap produk memiliki sheet inventory sendiri; status AVAILABLE dihitung jika data valid.
A6: J01...J04 | B6: Jenis Jasa: tidak mengganti logika persediaan/pengiriman jasa yang sudah berjalan.
A7: F01_Canva_Fresh | B7: Hanya 1 pesan template kustom. Produksi akun setelah order masuk; tidak konsumsi stock akun.
A8: STOCK PRODUCT | B8: Isi baris mulai 9; Status=AVAILABLE; minimal email+password, link, license, atau data bebas.
A9: EMAIL + PASSWORD | B9: Isi keduanya untuk format akun; dapat kosong jika menggunakan link/kode/custom.
A10: KODE / LINK / CUSTOM | B10: Salah satu diisi bila tidak menggunakan email+password.
A11: STOCK COUNT | B11: Menghitung stok valid yang AVAILABLE; RESERVED, SOLD, INVALID bukan tersedia.
A12: FRESH STOCK | B12: Tampil 1 hanya jika AKTIF dan pesan custom telah diisi; tidak berkurang setelah pesanan.
A13: PESAN CUSTOM | B13: Isi sendiri pada sheet Fresh; tetap gunakan copy aman dan review sebelum dipublikasikan.
A14: HARGA KOSONG | B14: UPI dan Plus reguler belum diberi harga; isi melalui Summary sebelum diimpor.
... A16: INTEGRASI | B16: Bot/web harus melakukan validasi, transaksi stok atomik, dan routing jenis terpisah; workbook hanya template.
A18: SKU | B18: Katalog | C18: Product | D18: Jenis | E18: Nama Sheet Stock
A19: PRD001 | B19: Gemini | C19: Gemini Google AI Plus 400GB 12 bulan | D19: Product | E19: P01_Gemini_Plus12
A20: PRD002 | B20: Gemini | C20: Gemini Google AI Pro 5TB 18 bulan | D20: Product | E20: P02_Gemini_Pro18
A21: PRD003 | B21: Gemini | C21: Gemini Google AI Ultra 20TB 24 bulan | D21: Product | E21: P03_Gemini_Ultra24
A22: PRD004 | B22: Claude | C22: Claude Pro 1 Bulan (Gift Pack) | D22: Product | E22: P04_Claude_Gift1
A23: PRD005 | B23: Claude | C23: Claude Pro 3 Bulan (Gift Pack) | D23: Product | E23: P05_Claude_Gift3
A24: PRD006 | B24: Claude | C24: Claude Pro 6 Bulan (Gift Pack) | D24: Product | E24: P06_Claude_Gift6
A25: PRD007 | B25: Claude | C25: Claude Pro 12 Bulan (Gift Pack) | D25: Product | E25: P07_Claude_Gift12
A26: PRD008 | B26: Claude | C26: Claude Startup ($1000) 6 bulan — Head Account | D26: Product | E26: P08_Claude_Head
A27: SRV001 | B27: Claude | C27: Claude Invite Reguler 1 bulan | D27: Jasa | E27: J01_Claude_Invite
A28: SRV002 | B28: Claude | C28: Claude Invite Startup per seat per bulan | D28: Jasa | E28: J02_Startup_Seat1
A29: SRV003 | B29: Claude | C29: Claude Invite Startup per seat 6 bulan | D29: Jasa | E29: J03_Startup_Seat6
... A39: PRD016 | B39: YouTube | C39: YouTube Premium (Akun Seller) 3 bulan | D39: Product | E39: P16_YouTube_3mo
A42: SHEET BARU | B42: FUNGSI
A43: Deskripsi & Aktivasi | B43: Fitur, benefit, cara aktivasi, garansi seller, risiko/ketentuan, sumber resmi, dan ringkasan teks untuk bot (21 produk).
A44: Catatan Verifikasi | B44: Daftar hal yang harus dicek sebelum deskripsi dipublikasikan, khususnya paket promosi, akun seller, program startup, dan layanan invite.
A45: Summary!H2:H22 | B45: Deskripsi lengkap multi-bagian. Jika importer bot membatasi panjang teks, gunakan kolom Ringkasan Bot di sheet Deskripsi & Aktivasi untuk tabel dan isi lengkap untuk detail.
A46: Benefit resmi ≠ hak seller | B46: Benefit paket resmi dapat berubah. Durasi promosi 18/24 bulan, garansi toko, harga, stok, dan mekanisme penyerahan wajib dibuktikan penjual.
A47: Keamanan & ketentuan | B47: Jangan mempublikasikan email/password stok. Kebijakan provider tentang transfer/resale, eligibility pendidikan, dan sharing household tetap berlaku.

Sheet P01_Gemini_Plus12
A1: PRD001 | Gemini Google AI Plus 400GB 12 bulan
A3: SKU | B3: PRD001
A4: STOK TERSEDIA | B4: =SUM(J9:J208) -> 0
A5: JENIS | B5: Product
A6: HARGA | B6: 15000
A7: GARANSI | B7: Full garansi 12 bulan
A8: Stock ID | B8: Status | C8: Format | D8: Email | E8: Password | F8: Redeem / Link | G8: License / Kode | H8: Data Bebas | I8: Catatan | J8: Valid Stock
J9: =IF(B9="AVAILABLE",IF(OR(AND(D9<>"",E9<>""),F9<>"",G9<>"",H9<>""),1,0),0) -> 0
J10: =IF(B10="AVAILABLE",IF(OR(AND(D10<>"",E10<>""),F10<>"",G10<>"",H10<>""),1,0),0) -> 0
J11: =IF(B11="AVAILABLE",IF(OR(AND(D11<>"",E11<>""),F11<>"",G11<>"",H11<>""),1,0),0) -> 0
J12: =IF(B12="AVAILABLE",IF(OR(AND(D12<>"",E12<>""),F12<>"",G12<>"",H12<>""),1,0),0) -> 0
J13: =IF(B13="AVAILABLE",IF(OR(AND(D13<>"",E13<>""),F13<>"",G13<>"",H13<>""),1,0),0) -> 0
J14: =IF(B14="AVAILABLE",IF(OR(AND(D14<>"",E14<>""),F14<>"",G14<>"",H14<>""),1,0),0) -> 0
J15: =IF(B15="AVAILABLE",IF(OR(AND(D15<>"",E15<>""),F15<>"",G15<>"",H15<>""),1,0),0) -> 0
J16: =IF(B16="AVAILABLE",IF(OR(AND(D16<>"",E16<>""),F16<>"",G16<>"",H16<>""),1,0),0) -> 0
J17: =IF(B17="AVAILABLE",IF(OR(AND(D17<>"",E17<>""),F17<>"",G17<>"",H17<>""),1,0),0) -> 0
J18: =IF(B18="AVAILABLE",IF(OR(AND(D18<>"",E18<>""),F18<>"",G18<>"",H18<>""),1,0),0) -> 0
J19: =IF(B19="AVAILABLE",IF(OR(AND(D19<>"",E19<>""),F19<>"",G19<>"",H19<>""),1,0),0) -> 0
J20: =IF(B20="AVAILABLE",IF(OR(AND(D20<>"",E20<>""),F20<>"",G20<>"",H20<>""),1,0),0) -> 0
... J208: =IF(B208="AVAILABLE",IF(OR(AND(D208<>"",E208<>""),F208<>"",G208<>"",H208<>""),1,0),0) -> 0
A210: PETUNJUK | B210: Isi 1 unit stok per baris. Email dan Password wajib berpasangan; atau isi Redeem Link / License / Data Bebas.

Sheet P02_Gemini_Pro18
A1: PRD002 | Gemini Google AI Pro 5TB 18 bulan
A3: SKU | B3: PRD002
A4: STOK TERSEDIA | B4: =SUM(J9:J208) -> 0
A5: JENIS | B5: Product
A6: HARGA | B6: 25000
A7: GARANSI | B7: 2 jam
A8: Stock ID | B8: Status | C8: Format | D8: Email | E8: Password | F8: Redeem / Link | G8: License / Kode | H8: Data Bebas | I8: Catatan | J8: Valid Stock
J9: =IF(B9="AVAILABLE",IF(OR(AND(D9<>"",E9<>""),F9<>"",G9<>"",H9<>""),1,0),0) -> 0
J10: =IF(B10="AVAILABLE",IF(OR(AND(D10<>"",E10<>""),F10<>"",G10<>"",H10<>""),1,0),0) -> 0
J11: =IF(B11="AVAILABLE",IF(OR(AND(D11<>"",E11<>""),F11<>"",G11<>"",H11<>""),1,0),0) -> 0
J12: =IF(B12="AVAILABLE",IF(OR(AND(D12<>"",E12<>""),F12<>"",G12<>"",H12<>""),1,0),0) -> 0
J13: =IF(B13="AVAILABLE",IF(OR(AND(D13<>"",E13<>""),F13<>"",G13<>"",H13<>""),1,0),0) -> 0
J14: =IF(B14="AVAILABLE",IF(OR(AND(D14<>"",E14<>""),F14<>"",G14<>"",H14<>""),1,0),0) -> 0
J15: =IF(B15="AVAILABLE",IF(OR(AND(D15<>"",E15<>""),F15<>"",G15<>"",H15<>""),1,0),0) -> 0
J16: =IF(B16="AVAILABLE",IF(OR(AND(D16<>"",E16<>""),F16<>"",G16<>"",H16<>""),1,0),0) -> 0
J17: =IF(B17="AVAILABLE",IF(OR(AND(D17<>"",E17<>""),F17<>"",G17<>"",H17<>""),1,0),0) -> 0
J18: =IF(B18="AVAILABLE",IF(OR(AND(D18<>"",E18<>""),F18<>"",G18<>"",H18<>""),1,0),0) -> 0
J19: =IF(B19="AVAILABLE",IF(OR(AND(D19<>"",E19<>""),F19<>"",G19<>"",H19<>""),1,0),0) -> 0
J20: =IF(B20="AVAILABLE",IF(OR(AND(D20<>"",E20<>""),F20<>"",G20<>"",H20<>""),1,0),0) -> 0
... J208: =IF(B208="AVAILABLE",IF(OR(AND(D208<>"",E208<>""),F208<>"",G208<>"",H208<>""),1,0),0) -> 0
A210: PETUNJUK | B210: Isi 1 unit stok per baris. Email dan Password wajib berpasangan; atau isi Redeem Link / License / Data Bebas.

Sheet P03_Gemini_Ultra24
A1: PRD003 | Gemini Google AI Ultra 20TB 24 bulan
A3: SKU | B3: PRD003
A4: STOK TERSEDIA | B4: =SUM(J9:J208) -> 0
A5: JENIS | B5: Product
A6: HARGA | B6: 155000
A7: GARANSI | B7: 6 bulan
A8: Stock ID | B8: Status | C8: Format | D8: Email | E8: Password | F8: Redeem / Link | G8: License / Kode | H8: Data Bebas | I8: Catatan | J8: Valid Stock
J9: =IF(B9="AVAILABLE",IF(OR(AND(D9<>"",E9<>""),F9<>"",G9<>"",H9<>""),1,0),0) -> 0
J10: =IF(B10="AVAILABLE",IF(OR(AND(D10<>"",E10<>""),F10<>"",G10<>"",H10<>""),1,0),0) -> 0
J11: =IF(B11="AVAILABLE",IF(OR(AND(D11<>"",E11<>""),F11<>"",G11<>"",H11<>""),1,0),0) -> 0
J12: =IF(B12="AVAILABLE",IF(OR(AND(D12<>"",E12<>""),F12<>"",G12<>"",H12<>""),1,0),0) -> 0
J13: =IF(B13="AVAILABLE",IF(OR(AND(D13<>"",E13<>""),F13<>"",G13<>"",H13<>""),1,0),0) -> 0
J14: =IF(B14="AVAILABLE",IF(OR(AND(D14<>"",E14<>""),F14<>"",G14<>"",H14<>""),1,0),0) -> 0
J15: =IF(B15="AVAILABLE",IF(OR(AND(D15<>"",E15<>""),F15<>"",G15<>"",H15<>""),1,0),0) -> 0
J16: =IF(B16="AVAILABLE",IF(OR(AND(D16<>"",E16<>""),F16<>"",G16<>"",H16<>""),1,0),0) -> 0
J17: =IF(B17="AVAILABLE",IF(OR(AND(D17<>"",E17<>""),F17<>"",G17<>"",H17<>""),1,0),0) -> 0
J18: =IF(B18="AVAILABLE",IF(OR(AND(D18<>"",E18<>""),F18<>"",G18<>"",H18<>""),1,0),0) -> 0
J19: =IF(B19="AVAILABLE",IF(OR(AND(D19<>"",E19<>""),F19<>"",G19<>"",H19<>""),1,0),0) -> 0
J20: =IF(B20="AVAILABLE",IF(OR(AND(D20<>"",E20<>""),F20<>"",G20<>"",H20<>""),1,0),0) -> 0
... J208: =IF(B208="AVAILABLE",IF(OR(AND(D208<>"",E208<>""),F208<>"",G208<>"",H208<>""),1,0),0) -> 0
A210: PETUNJUK | B210: Isi 1 unit stok per baris. Email dan Password wajib berpasangan; atau isi Redeem Link / License / Data Bebas.

Sheet P04_Claude_Gift1
A1: PRD004 | Claude Pro 1 Bulan (Gift Pack)
A3: SKU | B3: PRD004
A4: STOK TERSEDIA | B4: =SUM(J9:J208) -> 0
A5: JENIS | B5: Product
A6: HARGA | B6: 175000
A7: GARANSI | B7: 25 hari
A8: Stock ID | B8: Status | C8: Format | D8: Email | E8: Password | F8: Redeem / Link | G8: License / Kode | H8: Data Bebas | I8: Catatan | J8: Valid Stock
J9: =IF(B9="AVAILABLE",IF(OR(AND(D9<>"",E9<>""),F9<>"",G9<>"",H9<>""),1,0),0) -> 0
J10: =IF(B10="AVAILABLE",IF(OR(AND(D10<>"",E10<>""),F10<>"",G10<>"",H10<>""),1,0),0) -> 0
J11: =IF(B11="AVAILABLE",IF(OR(AND(D11<>"",E11<>""),F11<>"",G11<>"",H11<>""),1,0),0) -> 0
J12: =IF(B12="AVAILABLE",IF(OR(AND(D12<>"",E12<>""),F12<>"",G12<>"",H12<>""),1,0),0) -> 0
J13: =IF(B13="AVAILABLE",IF(OR(AND(D13<>"",E13<>""),F13<>"",G13<>"",H13<>""),1,0),0) -> 0
J14: =IF(B14="AVAILABLE",IF(OR(AND(D14<>"",E14<>""),F14<>"",G14<>"",H14<>""),1,0),0) -> 0
J15: =IF(B15="AVAILABLE",IF(OR(AND(D15<>"",E15<>""),F15<>"",G15<>"",H15<>""),1,0),0) -> 0
J16: =IF(B16="AVAILABLE",IF(OR(AND(D16<>"",E16<>""),F16<>"",G16<>"",H16<>""),1,0),0) -> 0
J17: =IF(B17="AVAILABLE",IF(OR(AND(D17<>"",E17<>""),F17<>"",G17<>"",H17<>""),1,0),0) -> 0
J18: =IF(B18="AVAILABLE",IF(OR(AND(D18<>"",E18<>""),F18<>"",G18<>"",H18<>""),1,0),0) -> 0
J19: =IF(B19="AVAILABLE",IF(OR(AND(D19<>"",E19<>""),F19<>"",G19<>"",H19<>""),1,0),0) -> 0
J20: =IF(B20="AVAILABLE",IF(OR(AND(D20<>"",E20<>""),F20<>"",G20<>"",H20<>""),1,0),0) -> 0
... J208: =IF(B208="AVAILABLE",IF(OR(AND(D208<>"",E208<>""),F208<>"",G208<>"",H208<>""),1,0),0) -> 0
A210: PETUNJUK | B210: Isi 1 unit stok per baris. Email dan Password wajib berpasangan; atau isi Redeem Link / License / Data Bebas.

Sheet P05_Claude_Gift3
A1: PRD005 | Claude Pro 3 Bulan (Gift Pack)
A3: SKU | B3: PRD005
A4: STOK TERSEDIA | B4: =SUM(J9:J208) -> 0
A5: JENIS | B5: Product
A6: HARGA | B6: 370000
A7: GARANSI | B7: 85 hari
A8: Stock ID | B8: Status | C8: Format | D8: Email | E8: Password | F8: Redeem / Link | G8: License / Kode | H8: Data Bebas | I8: Catatan | J8: Valid Stock
J9: =IF(B9="AVAILABLE",IF(OR(AND(D9<>"",E9<>""),F9<>"",G9<>"",H9<>""),1,0),0) -> 0
J10: =IF(B10="AVAILABLE",IF(OR(AND(D10<>"",E10<>""),F10<>"",G10<>"",H10<>""),1,0),0) -> 0
J11: =IF(B11="AVAILABLE",IF(OR(AND(D11<>"",E11<>""),F11<>"",G11<>"",H11<>""),1,0),0) -> 0
J12: =IF(B12="AVAILABLE",IF(OR(AND(D12<>"",E12<>""),F12<>"",G12<>"",H12<>""),1,0),0) -> 0
J13: =IF(B13="AVAILABLE",IF(OR(AND(D13<>"",E13<>""),F13<>"",G13<>"",H13<>""),1,0),0) -> 0
J14: =IF(B14="AVAILABLE",IF(OR(AND(D14<>"",E14<>""),F14<>"",G14<>"",H14<>""),1,0),0) -> 0
J15: =IF(B15="AVAILABLE",IF(OR(AND(D15<>"",E15<>""),F15<>"",G15<>"",H15<>""),1,0),0) -> 0
J16: =IF(B16="AVAILABLE",IF(OR(AND(D16<>"",E16<>""),F16<>"",G16<>"",H16<>""),1,0),0) -> 0
J17: =IF(B17="AVAILABLE",IF(OR(AND(D17<>"",E17<>""),F17<>"",G17<>"",H17<>""),1,0),0) -> 0
J18: =IF(B18="AVAILABLE",IF(OR(AND(D18<>"",E18<>""),F18<>"",G18<>"",H18<>""),1,0),0) -> 0
J19: =IF(B19="AVAILABLE",IF(OR(AND(D19<>"",E19<>""),F19<>"",G19<>"",H19<>""),1,0),0) -> 0
J20: =IF(B20="AVAILABLE",IF(OR(AND(D20<>"",E20<>""),F20<>"",G20<>"",H20<>""),1,0),0) -> 0
... J208: =IF(B208="AVAILABLE",IF(OR(AND(D208<>"",E208<>""),F208<>"",G208<>"",H208<>""),1,0),0) -> 0
A210: PETUNJUK | B210: Isi 1 unit stok per baris. Email dan Password wajib berpasangan; atau isi Redeem Link / License / Data Bebas.

Sheet P06_Claude_Gift6
A1: PRD006 | Claude Pro 6 Bulan (Gift Pack)
A3: SKU | B3: PRD006
A4: STOK TERSEDIA | B4: =SUM(J9:J208) -> 0
A5: JENIS | B5: Product
A6: HARGA | B6: 650000
A7: GARANSI | B7: 178 hari
A8: Stock ID | B8: Status | C8: Format | D8: Email | E8: Password | F8: Redeem / Link | G8: License / Kode | H8: Data Bebas | I8: Catatan | J8: Valid Stock
J9: =IF(B9="AVAILABLE",IF(OR(AND(D9<>"",E9<>""),F9<>"",G9<>"",H9<>""),1,0),0) -> 0
J10: =IF(B10="AVAILABLE",IF(OR(AND(D10<>"",E10<>""),F10<>"",G10<>"",H10<>""),1,0),0) -> 0
J11: =IF(B11="AVAILABLE",IF(OR(AND(D11<>"",E11<>""),F11<>"",G11<>"",H11<>""),1,0),0) -> 0
J12: =IF(B12="AVAILABLE",IF(OR(AND(D12<>"",E12<>""),F12<>"",G12<>"",H12<>""),1,0),0) -> 0
J13: =IF(B13="AVAILABLE",IF(OR(AND(D13<>"",E13<>""),F13<>"",G13<>"",H13<>""),1,0),0) -> 0
J14: =IF(B14="AVAILABLE",IF(OR(AND(D14<>"",E14<>""),F14<>"",G14<>"",H14<>""),1,0),0) -> 0
J15: =IF(B15="AVAILABLE",IF(OR(AND(D15<>"",E15<>""),F15<>"",G15<>"",H15<>""),1,0),0) -> 0
J16: =IF(B16="AVAILABLE",IF(OR(AND(D16<>"",E16<>""),F16<>"",G16<>"",H16<>""),1,0),0) -> 0
J17: =IF(B17="AVAILABLE",IF(OR(AND(D17<>"",E17<>""),F17<>"",G17<>"",H17<>""),1,0),0) -> 0
J18: =IF(B18="AVAILABLE",IF(OR(AND(D18<>"",E18<>""),F18<>"",G18<>"",H18<>""),1,0),0) -> 0
J19: =IF(B19="AVAILABLE",IF(OR(AND(D19<>"",E19<>""),F19<>"",G19<>"",H19<>""),1,0),0) -> 0
J20: =IF(B20="AVAILABLE",IF(OR(AND(D20<>"",E20<>""),F20<>"",G20<>"",H20<>""),1,0),0) -> 0
... J208: =IF(B208="AVAILABLE",IF(OR(AND(D208<>"",E208<>""),F208<>"",G208<>"",H208<>""),1,0),0) -> 0
A210: PETUNJUK | B210: Isi 1 unit stok per baris. Email dan Password wajib berpasangan; atau isi Redeem Link / License / Data Bebas.

Sheet P07_Claude_Gift12
A1: PRD007 | Claude Pro 12 Bulan (Gift Pack)
A3: SKU | B3: PRD007
A4: STOK TERSEDIA | B4: =SUM(J9:J208) -> 0
A5: JENIS | B5: Product
A6: HARGA | B6: 850000
A7: GARANSI | B7: 340 hari
A8: Stock ID | B8: Status | C8: Format | D8: Email | E8: Password | F8: Redeem / Link | G8: License / Kode | H8: Data Bebas | I8: Catatan | J8: Valid Stock
J9: =IF(B9="AVAILABLE",IF(OR(AND(D9<>"",E9<>""),F9<>"",G9<>"",H9<>""),1,0),0) -> 0
J10: =IF(B10="AVAILABLE",IF(OR(AND(D10<>"",E10<>""),F10<>"",G10<>"",H10<>""),1,0),0) -> 0
J11: =IF(B11="AVAILABLE",IF(OR(AND(D11<>"",E11<>""),F11<>"",G11<>"",H11<>""),1,0),0) -> 0
J12: =IF(B12="AVAILABLE",IF(OR(AND(D12<>"",E12<>""),F12<>"",G12<>"",H12<>""),1,0),0) -> 0
J13: =IF(B13="AVAILABLE",IF(OR(AND(D13<>"",E13<>""),F13<>"",G13<>"",H13<>""),1,0),0) -> 0
J14: =IF(B14="AVAILABLE",IF(OR(AND(D14<>"",E14<>""),F14<>"",G14<>"",H14<>""),1,0),0) -> 0
J15: =IF(B15="AVAILABLE",IF(OR(AND(D15<>"",E15<>""),F15<>"",G15<>"",H15<>""),1,0),0) -> 0
J16: =IF(B16="AVAILABLE",IF(OR(AND(D16<>"",E16<>""),F16<>"",G16<>"",H16<>""),1,0),0) -> 0
J17: =IF(B17="AVAILABLE",IF(OR(AND(D17<>"",E17<>""),F17<>"",G17<>"",H17<>""),1,0),0) -> 0
J18: =IF(B18="AVAILABLE",IF(OR(AND(D18<>"",E18<>""),F18<>"",G18<>"",H18<>""),1,0),0) -> 0
J19: =IF(B19="AVAILABLE",IF(OR(AND(D19<>"",E19<>""),F19<>"",G19<>"",H19<>""),1,0),0) -> 0
J20: =IF(B20="AVAILABLE",IF(OR(AND(D20<>"",E20<>""),F20<>"",G20<>"",H20<>""),1,0),0) -> 0
... J208: =IF(B208="AVAILABLE",IF(OR(AND(D208<>"",E208<>""),F208<>"",G208<>"",H208<>""),1,0),0) -> 0
A210: PETUNJUK | B210: Isi 1 unit stok per baris. Email dan Password wajib berpasangan; atau isi Redeem Link / License / Data Bebas.

Sheet P08_Claude_Head
A1: PRD008 | Claude Startup ($1000) 6 bulan — Head Account
A3: SKU | B3: PRD008
A4: STOK TERSEDIA | B4: =SUM(J9:J208) -> 0
A5: JENIS | B5: Product
A6: HARGA | B6: 7900000
A7: GARANSI | B7: 1 bulan
A8: Stock ID | B8: Status | C8: Format | D8: Email | E8: Password | F8: Redeem / Link | G8: License / Kode | H8: Data Bebas | I8: Catatan | J8: Valid Stock
J9: =IF(B9="AVAILABLE",IF(OR(AND(D9<>"",E9<>""),F9<>"",G9<>"",H9<>""),1,0),0) -> 0
J10: =IF(B10="AVAILABLE",IF(OR(AND(D10<>"",E10<>""),F10<>"",G10<>"",H10<>""),1,0),0) -> 0
J11: =IF(B11="AVAILABLE",IF(OR(AND(D11<>"",E11<>""),F11<>"",G11<>"",H11<>""),1,0),0) -> 0
J12: =IF(B12="AVAILABLE",IF(OR(AND(D12<>"",E12<>""),F12<>"",G12<>"",H12<>""),1,0),0) -> 0
J13: =IF(B13="AVAILABLE",IF(OR(AND(D13<>"",E13<>""),F13<>"",G13<>"",H13<>""),1,0),0) -> 0
J14: =IF(B14="AVAILABLE",IF(OR(AND(D14<>"",E14<>""),F14<>"",G14<>"",H14<>""),1,0),0) -> 0
J15: =IF(B15="AVAILABLE",IF(OR(AND(D15<>"",E15<>""),F15<>"",G15<>"",H15<>""),1,0),0) -> 0
J16: =IF(B16="AVAILABLE",IF(OR(AND(D16<>"",E16<>""),F16<>"",G16<>"",H16<>""),1,0),0) -> 0
J17: =IF(B17="AVAILABLE",IF(OR(AND(D17<>"",E17<>""),F17<>"",G17<>"",H17<>""),1,0),0) -> 0
J18: =IF(B18="AVAILABLE",IF(OR(AND(D18<>"",E18<>""),F18<>"",G18<>"",H18<>""),1,0),0) -> 0
J19: =IF(B19="AVAILABLE",IF(OR(AND(D19<>"",E19<>""),F19<>"",G19<>"",H19<>""),1,0),0) -> 0
J20: =IF(B20="AVAILABLE",IF(OR(AND(D20<>"",E20<>""),F20<>"",G20<>"",H20<>""),1,0),0) -> 0
... J208: =IF(B208="AVAILABLE",IF(OR(AND(D208<>"",E208<>""),F208<>"",G208<>"",H208<>""),1,0),0) -> 0
A210: PETUNJUK | B210: Isi 1 unit stok per baris. Email dan Password wajib berpasangan; atau isi Redeem Link / License / Data Bebas.

Sheet J01_Claude_Invite
A1: SRV001 | Claude Invite Reguler 1 bulan
A3: SKU | B3: SRV001
A4: STOK TERSEDIA | B4: DARI BOT
A5: JENIS | B5: Jasa
A6: HARGA | B6: 120000
A7: GARANSI | B7: Belum ditentukan
A9: PENGATURAN | B9: NILAI | C9: STATUS | D9: CATATAN | E9: No | F9: Tanggal | G9: Ref Order | H9: Catatan Admin
A10: Workflow | B10: Ikuti sistem jasa eksisting | C10: TIDAK DIUBAH | D10: Tidak membuat inventori akun/kode baru.
A11: Pemesanan | B11: Gunakan handler jasa lama | C11: TIDAK DIUBAH | D11: Pertahankan pembayaran dan verifikasi lama.
A12: Pesan ke pembeli | B12: Isi pada bot/web yang sudah ada | C12: KUSTOM | D12: File ini tidak mengubah isi pesan otomatis.
A13: Stok | B13: Mengikuti mekanisme jasa lama | C13: EKSTERNAL | D13: Summary hanya menandai DARI BOT.

Sheet J02_Startup_Seat1
A1: SRV002 | Claude Invite Startup per seat per bulan
A3: SKU | B3: SRV002
A4: STOK TERSEDIA | B4: DARI BOT
A5: JENIS | B5: Jasa
A6: HARGA | B6: 600000
A7: GARANSI | B7: Belum ditentukan
A9: PENGATURAN | B9: NILAI | C9: STATUS | D9: CATATAN | E9: No | F9: Tanggal | G9: Ref Order | H9: Catatan Admin
A10: Workflow | B10: Ikuti sistem jasa eksisting | C10: TIDAK DIUBAH | D10: Tidak membuat inventori akun/kode baru.
A11: Pemesanan | B11: Gunakan handler jasa lama | C11: TIDAK DIUBAH | D11: Pertahankan pembayaran dan verifikasi lama.
A12: Pesan ke pembeli | B12: Isi pada bot/web yang sudah ada | C12: KUSTOM | D12: File ini tidak mengubah isi pesan otomatis.
A13: Stok | B13: Mengikuti mekanisme jasa lama | C13: EKSTERNAL | D13: Summary hanya menandai DARI BOT.

Sheet J03_Startup_Seat6
A1: SRV003 | Claude Invite Startup per seat 6 bulan
A3: SKU | B3: SRV003
A4: STOK TERSEDIA | B4: DARI BOT
A5: JENIS | B5: Jasa
A6: HARGA | B6: 2780000
A7: GARANSI | B7: Belum ditentukan
A9: PENGATURAN | B9: NILAI | C9: STATUS | D9: CATATAN | E9: No | F9: Tanggal | G9: Ref Order | H9: Catatan Admin
A10: Workflow | B10: Ikuti sistem jasa eksisting | C10: TIDAK DIUBAH | D10: Tidak membuat inventori akun/kode baru.
A11: Pemesanan | B11: Gunakan handler jasa lama | C11: TIDAK DIUBAH | D11: Pertahankan pembayaran dan verifikasi lama.
A12: Pesan ke pembeli | B12: Isi pada bot/web yang sudah ada | C12: KUSTOM | D12: File ini tidak mengubah isi pesan otomatis.
A13: Stok | B13: Mengikuti mekanisme jasa lama | C13: EKSTERNAL | D13: Summary hanya menandai DARI BOT.

Sheet P09_GPT_UPI30
A1: PRD009 | ChatGPT Plus UPI 30 hari
A3: SKU | B3: PRD009
A4: STOK TERSEDIA | B4: =SUM(J9:J208) -> 0
A5: JENIS | B5: Product
A6: HARGA
A7: GARANSI | B7: 7 hari
A8: Stock ID | B8: Status | C8: Format | D8: Email | E8: Password | F8: Redeem / Link | G8: License / Kode | H8: Data Bebas | I8: Catatan | J8: Valid Stock
J9: =IF(B9="AVAILABLE",IF(OR(AND(D9<>"",E9<>""),F9<>"",G9<>"",H9<>""),1,0),0) -> 0
J10: =IF(B10="AVAILABLE",IF(OR(AND(D10<>"",E10<>""),F10<>"",G10<>"",H10<>""),1,0),0) -> 0
J11: =IF(B11="AVAILABLE",IF(OR(AND(D11<>"",E11<>""),F11<>"",G11<>"",H11<>""),1,0),0) -> 0
J12: =IF(B12="AVAILABLE",IF(OR(AND(D12<>"",E12<>""),F12<>"",G12<>"",H12<>""),1,0),0) -> 0
J13: =IF(B13="AVAILABLE",IF(OR(AND(D13<>"",E13<>""),F13<>"",G13<>"",H13<>""),1,0),0) -> 0
J14: =IF(B14="AVAILABLE",IF(OR(AND(D14<>"",E14<>""),F14<>"",G14<>"",H14<>""),1,0),0) -> 0
J15: =IF(B15="AVAILABLE",IF(OR(AND(D15<>"",E15<>""),F15<>"",G15<>"",H15<>""),1,0),0) -> 0
J16: =IF(B16="AVAILABLE",IF(OR(AND(D16<>"",E16<>""),F16<>"",G16<>"",H16<>""),1,0),0) -> 0
J17: =IF(B17="AVAILABLE",IF(OR(AND(D17<>"",E17<>""),F17<>"",G17<>"",H17<>""),1,0),0) -> 0
J18: =IF(B18="AVAILABLE",IF(OR(AND(D18<>"",E18<>""),F18<>"",G18<>"",H18<>""),1,0),0) -> 0
J19: =IF(B19="AVAILABLE",IF(OR(AND(D19<>"",E19<>""),F19<>"",G19<>"",H19<>""),1,0),0) -> 0
J20: =IF(B20="AVAILABLE",IF(OR(AND(D20<>"",E20<>""),F20<>"",G20<>"",H20<>""),1,0),0) -> 0
... J208: =IF(B208="AVAILABLE",IF(OR(AND(D208<>"",E208<>""),F208<>"",G208<>"",H208<>""),1,0),0) -> 0
A210: PETUNJUK | B210: Isi 1 unit stok per baris. Email dan Password wajib berpasangan; atau isi Redeem Link / License / Data Bebas.

Sheet P10_GPT_Reguler1
A1: PRD010 | ChatGPT Plus Reguler 1 bulan
A3: SKU | B3: PRD010
A4: STOK TERSEDIA | B4: =SUM(J9:J208) -> 0
A5: JENIS | B5: Product
A6: HARGA
A7: GARANSI | B7: 20 hari
A8: Stock ID | B8: Status | C8: Format | D8: Email | E8: Password | F8: Redeem / Link | G8: License / Kode | H8: Data Bebas | I8: Catatan | J8: Valid Stock
J9: =IF(B9="AVAILABLE",IF(OR(AND(D9<>"",E9<>""),F9<>"",G9<>"",H9<>""),1,0),0) -> 0
J10: =IF(B10="AVAILABLE",IF(OR(AND(D10<>"",E10<>""),F10<>"",G10<>"",H10<>""),1,0),0) -> 0
J11: =IF(B11="AVAILABLE",IF(OR(AND(D11<>"",E11<>""),F11<>"",G11<>"",H11<>""),1,0),0) -> 0
J12: =IF(B12="AVAILABLE",IF(OR(AND(D12<>"",E12<>""),F12<>"",G12<>"",H12<>""),1,0),0) -> 0
J13: =IF(B13="AVAILABLE",IF(OR(AND(D13<>"",E13<>""),F13<>"",G13<>"",H13<>""),1,0),0) -> 0
J14: =IF(B14="AVAILABLE",IF(OR(AND(D14<>"",E14<>""),F14<>"",G14<>"",H14<>""),1,0),0) -> 0
J15: =IF(B15="AVAILABLE",IF(OR(AND(D15<>"",E15<>""),F15<>"",G15<>"",H15<>""),1,0),0) -> 0
J16: =IF(B16="AVAILABLE",IF(OR(AND(D16<>"",E16<>""),F16<>"",G16<>"",H16<>""),1,0),0) -> 0
J17: =IF(B17="AVAILABLE",IF(OR(AND(D17<>"",E17<>""),F17<>"",G17<>"",H17<>""),1,0),0) -> 0
J18: =IF(B18="AVAILABLE",IF(OR(AND(D18<>"",E18<>""),F18<>"",G18<>"",H18<>""),1,0),0) -> 0
J19: =IF(B19="AVAILABLE",IF(OR(AND(D19<>"",E19<>""),F19<>"",G19<>"",H19<>""),1,0),0) -> 0
J20: =IF(B20="AVAILABLE",IF(OR(AND(D20<>"",E20<>""),F20<>"",G20<>"",H20<>""),1,0),0) -> 0
... J208: =IF(B208="AVAILABLE",IF(OR(AND(D208<>"",E208<>""),F208<>"",G208<>"",H208<>""),1,0),0) -> 0
A210: PETUNJUK | B210: Isi 1 unit stok per baris. Email dan Password wajib berpasangan; atau isi Redeem Link / License / Data Bebas.

Sheet P11_GPT_Trial30
A1: PRD011 | ChatGPT Plus Trial 30 hari
A3: SKU | B3: PRD011
A4: STOK TERSEDIA | B4: =SUM(J9:J208) -> 0
A5: JENIS | B5: Product
A6: HARGA | B6: 89000
A7: GARANSI | B7: Full garansi 30 hari
A8: Stock ID | B8: Status | C8: Format | D8: Email | E8: Password | F8: Redeem / Link | G8: License / Kode | H8: Data Bebas | I8: Catatan | J8: Valid Stock
J9: =IF(B9="AVAILABLE",IF(OR(AND(D9<>"",E9<>""),F9<>"",G9<>"",H9<>""),1,0),0) -> 0
J10: =IF(B10="AVAILABLE",IF(OR(AND(D10<>"",E10<>""),F10<>"",G10<>"",H10<>""),1,0),0) -> 0
J11: =IF(B11="AVAILABLE",IF(OR(AND(D11<>"",E11<>""),F11<>"",G11<>"",H11<>""),1,0),0) -> 0
J12: =IF(B12="AVAILABLE",IF(OR(AND(D12<>"",E12<>""),F12<>"",G12<>"",H12<>""),1,0),0) -> 0
J13: =IF(B13="AVAILABLE",IF(OR(AND(D13<>"",E13<>""),F13<>"",G13<>"",H13<>""),1,0),0) -> 0
J14: =IF(B14="AVAILABLE",IF(OR(AND(D14<>"",E14<>""),F14<>"",G14<>"",H14<>""),1,0),0) -> 0
J15: =IF(B15="AVAILABLE",IF(OR(AND(D15<>"",E15<>""),F15<>"",G15<>"",H15<>""),1,0),0) -> 0
J16: =IF(B16="AVAILABLE",IF(OR(AND(D16<>"",E16<>""),F16<>"",G16<>"",H16<>""),1,0),0) -> 0
J17: =IF(B17="AVAILABLE",IF(OR(AND(D17<>"",E17<>""),F17<>"",G17<>"",H17<>""),1,0),0) -> 0
J18: =IF(B18="AVAILABLE",IF(OR(AND(D18<>"",E18<>""),F18<>"",G18<>"",H18<>""),1,0),0) -> 0
J19: =IF(B19="AVAILABLE",IF(OR(AND(D19<>"",E19<>""),F19<>"",G19<>"",H19<>""),1,0),0) -> 0
J20: =IF(B20="AVAILABLE",IF(OR(AND(D20<>"",E20<>""),F20<>"",G20<>"",H20<>""),1,0),0) -> 0
... J208: =IF(B208="AVAILABLE",IF(OR(AND(D208<>"",E208<>""),F208<>"",G208<>"",H208<>""),1,0),0) -> 0
A210: PETUNJUK | B210: Isi 1 unit stok per baris. Email dan Password wajib berpasangan; atau isi Redeem Link / License / Data Bebas.

Sheet P12_GPT_Trial25
A1: PRD012 | ChatGPT Plus Trial 25 hari
A3: SKU | B3: PRD012
A4: STOK TERSEDIA | B4: =SUM(J9:J208) -> 0
A5: JENIS | B5: Product
A6: HARGA | B6: 78000
A7: GARANSI | B7: Full garansi 25 hari
A8: Stock ID | B8: Status | C8: Format | D8: Email | E8: Password | F8: Redeem / Link | G8: License / Kode | H8: Data Bebas | I8: Catatan | J8: Valid Stock
J9: =IF(B9="AVAILABLE",IF(OR(AND(D9<>"",E9<>""),F9<>"",G9<>"",H9<>""),1,0),0) -> 0
J10: =IF(B10="AVAILABLE",IF(OR(AND(D10<>"",E10<>""),F10<>"",G10<>"",H10<>""),1,0),0) -> 0
J11: =IF(B11="AVAILABLE",IF(OR(AND(D11<>"",E11<>""),F11<>"",G11<>"",H11<>""),1,0),0) -> 0
J12: =IF(B12="AVAILABLE",IF(OR(AND(D12<>"",E12<>""),F12<>"",G12<>"",H12<>""),1,0),0) -> 0
J13: =IF(B13="AVAILABLE",IF(OR(AND(D13<>"",E13<>""),F13<>"",G13<>"",H13<>""),1,0),0) -> 0
J14: =IF(B14="AVAILABLE",IF(OR(AND(D14<>"",E14<>""),F14<>"",G14<>"",H14<>""),1,0),0) -> 0
J15: =IF(B15="AVAILABLE",IF(OR(AND(D15<>"",E15<>""),F15<>"",G15<>"",H15<>""),1,0),0) -> 0
J16: =IF(B16="AVAILABLE",IF(OR(AND(D16<>"",E16<>""),F16<>"",G16<>"",H16<>""),1,0),0) -> 0
J17: =IF(B17="AVAILABLE",IF(OR(AND(D17<>"",E17<>""),F17<>"",G17<>"",H17<>""),1,0),0) -> 0
J18: =IF(B18="AVAILABLE",IF(OR(AND(D18<>"",E18<>""),F18<>"",G18<>"",H18<>""),1,0),0) -> 0
J19: =IF(B19="AVAILABLE",IF(OR(AND(D19<>"",E19<>""),F19<>"",G19<>"",H19<>""),1,0),0) -> 0
J20: =IF(B20="AVAILABLE",IF(OR(AND(D20<>"",E20<>""),F20<>"",G20<>"",H20<>""),1,0),0) -> 0
... J208: =IF(B208="AVAILABLE",IF(OR(AND(D208<>"",E208<>""),F208<>"",G208<>"",H208<>""),1,0),0) -> 0
A210: PETUNJUK | B210: Isi 1 unit stok per baris. Email dan Password wajib berpasangan; atau isi Redeem Link / License / Data Bebas.

Sheet P13_GPT_Trial15
A1: PRD013 | ChatGPT Plus Trial 15 hari
A3: SKU | B3: PRD013
A4: STOK TERSEDIA | B4: =SUM(J9:J208) -> 0
A5: JENIS | B5: Product
A6: HARGA | B6: 55000
A7: GARANSI | B7: Full garansi 15 hari
A8: Stock ID | B8: Status | C8: Format | D8: Email | E8: Password | F8: Redeem / Link | G8: License / Kode | H8: Data Bebas | I8: Catatan | J8: Valid Stock
J9: =IF(B9="AVAILABLE",IF(OR(AND(D9<>"",E9<>""),F9<>"",G9<>"",H9<>""),1,0),0) -> 0
J10: =IF(B10="AVAILABLE",IF(OR(AND(D10<>"",E10<>""),F10<>"",G10<>"",H10<>""),1,0),0) -> 0
J11: =IF(B11="AVAILABLE",IF(OR(AND(D11<>"",E11<>""),F11<>"",G11<>"",H11<>""),1,0),0) -> 0
J12: =IF(B12="AVAILABLE",IF(OR(AND(D12<>"",E12<>""),F12<>"",G12<>"",H12<>""),1,0),0) -> 0
J13: =IF(B13="AVAILABLE",IF(OR(AND(D13<>"",E13<>""),F13<>"",G13<>"",H13<>""),1,0),0) -> 0
J14: =IF(B14="AVAILABLE",IF(OR(AND(D14<>"",E14<>""),F14<>"",G14<>"",H14<>""),1,0),0) -> 0
J15: =IF(B15="AVAILABLE",IF(OR(AND(D15<>"",E15<>""),F15<>"",G15<>"",H15<>""),1,0),0) -> 0
J16: =IF(B16="AVAILABLE",IF(OR(AND(D16<>"",E16<>""),F16<>"",G16<>"",H16<>""),1,0),0) -> 0
J17: =IF(B17="AVAILABLE",IF(OR(AND(D17<>"",E17<>""),F17<>"",G17<>"",H17<>""),1,0),0) -> 0
J18: =IF(B18="AVAILABLE",IF(OR(AND(D18<>"",E18<>""),F18<>"",G18<>"",H18<>""),1,0),0) -> 0
J19: =IF(B19="AVAILABLE",IF(OR(AND(D19<>"",E19<>""),F19<>"",G19<>"",H19<>""),1,0),0) -> 0
J20: =IF(B20="AVAILABLE",IF(OR(AND(D20<>"",E20<>""),F20<>"",G20<>"",H20<>""),1,0),0) -> 0
... J208: =IF(B208="AVAILABLE",IF(OR(AND(D208<>"",E208<>""),F208<>"",G208<>"",H208<>""),1,0),0) -> 0
A210: PETUNJUK | B210: Isi 1 unit stok per baris. Email dan Password wajib berpasangan; atau isi Redeem Link / License / Data Bebas.

Sheet P14_GPT_Trial7
A1: PRD014 | ChatGPT Plus Trial 7 hari
A3: SKU | B3: PRD014
A4: STOK TERSEDIA | B4: =SUM(J9:J208) -> 0
A5: JENIS | B5: Product
A6: HARGA | B6: 45000
A7: GARANSI | B7: Full garansi 7 hari
A8: Stock ID | B8: Status | C8: Format | D8: Email | E8: Password | F8: Redeem / Link | G8: License / Kode | H8: Data Bebas | I8: Catatan | J8: Valid Stock
J9: =IF(B9="AVAILABLE",IF(OR(AND(D9<>"",E9<>""),F9<>"",G9<>"",H9<>""),1,0),0) -> 0
J10: =IF(B10="AVAILABLE",IF(OR(AND(D10<>"",E10<>""),F10<>"",G10<>"",H10<>""),1,0),0) -> 0
J11: =IF(B11="AVAILABLE",IF(OR(AND(D11<>"",E11<>""),F11<>"",G11<>"",H11<>""),1,0),0) -> 0
J12: =IF(B12="AVAILABLE",IF(OR(AND(D12<>"",E12<>""),F12<>"",G12<>"",H12<>""),1,0),0) -> 0
J13: =IF(B13="AVAILABLE",IF(OR(AND(D13<>"",E13<>""),F13<>"",G13<>"",H13<>""),1,0),0) -> 0
J14: =IF(B14="AVAILABLE",IF(OR(AND(D14<>"",E14<>""),F14<>"",G14<>"",H14<>""),1,0),0) -> 0
J15: =IF(B15="AVAILABLE",IF(OR(AND(D15<>"",E15<>""),F15<>"",G15<>"",H15<>""),1,0),0) -> 0
J16: =IF(B16="AVAILABLE",IF(OR(AND(D16<>"",E16<>""),F16<>"",G16<>"",H16<>""),1,0),0) -> 0
J17: =IF(B17="AVAILABLE",IF(OR(AND(D17<>"",E17<>""),F17<>"",G17<>"",H17<>""),1,0),0) -> 0
J18: =IF(B18="AVAILABLE",IF(OR(AND(D18<>"",E18<>""),F18<>"",G18<>"",H18<>""),1,0),0) -> 0
J19: =IF(B19="AVAILABLE",IF(OR(AND(D19<>"",E19<>""),F19<>"",G19<>"",H19<>""),1,0),0) -> 0
J20: =IF(B20="AVAILABLE",IF(OR(AND(D20<>"",E20<>""),F20<>"",G20<>"",H20<>""),1,0),0) -> 0
... J208: =IF(B208="AVAILABLE",IF(OR(AND(D208<>"",E208<>""),F208<>"",G208<>"",H208<>""),1,0),0) -> 0
A210: PETUNJUK | B210: Isi 1 unit stok per baris. Email dan Password wajib berpasangan; atau isi Redeem Link / License / Data Bebas.

Sheet J04_Muse_Referral
A1: SRV004 | Muse Token 3B (Referral)
A3: SKU | B3: SRV004
A4: STOK TERSEDIA | B4: DARI BOT
A5: JENIS | B5: Jasa
A6: HARGA | B6: 25000
A7: GARANSI | B7: Tidak ada
A9: PENGATURAN | B9: NILAI | C9: STATUS | D9: CATATAN | E9: No | F9: Tanggal | G9: Ref Order | H9: Catatan Admin
A10: Workflow | B10: Ikuti sistem jasa eksisting | C10: TIDAK DIUBAH | D10: Tidak membuat inventori akun/kode baru.
A11: Pemesanan | B11: Gunakan handler jasa lama | C11: TIDAK DIUBAH | D11: Pertahankan pembayaran dan verifikasi lama.
A12: Pesan ke pembeli | B12: Isi pada bot/web yang sudah ada | C12: KUSTOM | D12: File ini tidak mengubah isi pesan otomatis.
A13: Stok | B13: Mengikuti mekanisme jasa lama | C13: EKSTERNAL | D13: Summary hanya menandai DARI BOT.

Sheet F01_Canva_Fresh
A1: FBM001 | Canva Education Lifetime — Invite
A3: SKU | B3: FBM001
A4: STOK TERSEDIA | B4: =IF(AND(B14="AKTIF",LEN(TRIM(B9))>0),1,0) -> 0
A5: JENIS | B5: FRESH BY MADE
A6: HARGA | B6: 15000
A7: GARANSI | B7: Belum ditentukan
A9: PESAN ORDER KUSTOM
A14: STATUS PENJUALAN | B14: NONAKTIF
A16: CARA KERJA
A17: Stok yang tampil | B17: 1 jika AKTIF dan pesan custom terisi; selain itu 0.
A18: Saat order masuk | B18: Gunakan 1 pesan template yang sama untuk setiap order.
A19: Pembuatan akun | B19: Diproses setelah order masuk, bukan stok akun ready.
A20: Pengiriman pesan | B20: Isi template ini sendiri; bot/web memakai template yang dikonfigurasi.
A22: Ref Order | B22: Tanggal Masuk | C22: Status Proses | D22: Catatan

Sheet P15_Netflix_1P1U
A1: PRD015 | Netflix 1P1U
A3: SKU | B3: PRD015
A4: STOK TERSEDIA | B4: =SUM(J9:J208) -> 0
A5: JENIS | B5: Product
A6: HARGA | B6: 45000
A7: GARANSI | B7: Full garansi (durasi belum ditentukan)
A8: Stock ID | B8: Status | C8: Format | D8: Email | E8: Password | F8: Redeem / Link | G8: License / Kode | H8: Data Bebas | I8: Catatan | J8: Valid Stock
J9: =IF(B9="AVAILABLE",IF(OR(AND(D9<>"",E9<>""),F9<>"",G9<>"",H9<>""),1,0),0) -> 0
J10: =IF(B10="AVAILABLE",IF(OR(AND(D10<>"",E10<>""),F10<>"",G10<>"",H10<>""),1,0),0) -> 0
J11: =IF(B11="AVAILABLE",IF(OR(AND(D11<>"",E11<>""),F11<>"",G11<>"",H11<>""),1,0),0) -> 0
J12: =IF(B12="AVAILABLE",IF(OR(AND(D12<>"",E12<>""),F12<>"",G12<>"",H12<>""),1,0),0) -> 0
J13: =IF(B13="AVAILABLE",IF(OR(AND(D13<>"",E13<>""),F13<>"",G13<>"",H13<>""),1,0),0) -> 0
J14: =IF(B14="AVAILABLE",IF(OR(AND(D14<>"",E14<>""),F14<>"",G14<>"",H14<>""),1,0),0) -> 0
J15: =IF(B15="AVAILABLE",IF(OR(AND(D15<>"",E15<>""),F15<>"",G15<>"",H15<>""),1,0),0) -> 0
J16: =IF(B16="AVAILABLE",IF(OR(AND(D16<>"",E16<>""),F16<>"",G16<>"",H16<>""),1,0),0) -> 0
J17: =IF(B17="AVAILABLE",IF(OR(AND(D17<>"",E17<>""),F17<>"",G17<>"",H17<>""),1,0),0) -> 0
J18: =IF(B18="AVAILABLE",IF(OR(AND(D18<>"",E18<>""),F18<>"",G18<>"",H18<>""),1,0),0) -> 0
J19: =IF(B19="AVAILABLE",IF(OR(AND(D19<>"",E19<>""),F19<>"",G19<>"",H19<>""),1,0),0) -> 0
J20: =IF(B20="AVAILABLE",IF(OR(AND(D20<>"",E20<>""),F20<>"",G20<>"",H20<>""),1,0),0) -> 0
... J208: =IF(B208="AVAILABLE",IF(OR(AND(D208<>"",E208<>""),F208<>"",G208<>"",H208<>""),1,0),0) -> 0
A210: PETUNJUK | B210: Isi 1 unit stok per baris. Email dan Password wajib berpasangan; atau isi Redeem Link / License / Data Bebas.

Sheet P16_YouTube_3mo
A1: PRD016 | YouTube Premium (Akun Seller) 3 bulan
A3: SKU | B3: PRD016
A4: STOK TERSEDIA | B4: =SUM(J9:J208) -> 0
A5: JENIS | B5: Product
A6: HARGA | B6: 45000
A7: GARANSI | B7: 2 bulan
A8: Stock ID | B8: Status | C8: Format | D8: Email | E8: Password | F8: Redeem / Link | G8: License / Kode | H8: Data Bebas | I8: Catatan | J8: Valid Stock
J9: =IF(B9="AVAILABLE",IF(OR(AND(D9<>"",E9<>""),F9<>"",G9<>"",H9<>""),1,0),0) -> 0
J10: =IF(B10="AVAILABLE",IF(OR(AND(D10<>"",E10<>""),F10<>"",G10<>"",H10<>""),1,0),0) -> 0
J11: =IF(B11="AVAILABLE",IF(OR(AND(D11<>"",E11<>""),F11<>"",G11<>"",H11<>""),1,0),0) -> 0
J12: =IF(B12="AVAILABLE",IF(OR(AND(D12<>"",E12<>""),F12<>"",G12<>"",H12<>""),1,0),0) -> 0
J13: =IF(B13="AVAILABLE",IF(OR(AND(D13<>"",E13<>""),F13<>"",G13<>"",H13<>""),1,0),0) -> 0
J14: =IF(B14="AVAILABLE",IF(OR(AND(D14<>"",E14<>""),F14<>"",G14<>"",H14<>""),1,0),0) -> 0
J15: =IF(B15="AVAILABLE",IF(OR(AND(D15<>"",E15<>""),F15<>"",G15<>"",H15<>""),1,0),0) -> 0
J16: =IF(B16="AVAILABLE",IF(OR(AND(D16<>"",E16<>""),F16<>"",G16<>"",H16<>""),1,0),0) -> 0
J17: =IF(B17="AVAILABLE",IF(OR(AND(D17<>"",E17<>""),F17<>"",G17<>"",H17<>""),1,0),0) -> 0
J18: =IF(B18="AVAILABLE",IF(OR(AND(D18<>"",E18<>""),F18<>"",G18<>"",H18<>""),1,0),0) -> 0
J19: =IF(B19="AVAILABLE",IF(OR(AND(D19<>"",E19<>""),F19<>"",G19<>"",H19<>""),1,0),0) -> 0
J20: =IF(B20="AVAILABLE",IF(OR(AND(D20<>"",E20<>""),F20<>"",G20<>"",H20<>""),1,0),0) -> 0
... J208: =IF(B208="AVAILABLE",IF(OR(AND(D208<>"",E208<>""),F208<>"",G208<>"",H208<>""),1,0),0) -> 0
A210: PETUNJUK | B210: Isi 1 unit stok per baris. Email dan Password wajib berpasangan; atau isi Redeem Link / License / Data Bebas.

Sheet Deskripsi & Aktivasi
A1: SKU | B1: Katalog | C1: Product | D1: Fitur Utama | E1: Benefit | F1: Cara Aktivasi | G1: Garansi Seller | H1: Catatan / Risiko | I1: Sumber Resmi | J1: Ringkasan Bot
